<?xml version="1.0"?>
<robot name="velvet_fingers" xmlns:xacro="http://www.ros.org/wiki/xacro">

  <!-- Import all Gazebo-customization elements, including Gazebo colors -->
  <xacro:include filename="$(find velvet_fingers_description)/urdf/velvet_fingers.gazebo.xacro" />
  <!-- Import Transmissions -->
  <xacro:include filename="$(find velvet_fingers_description)/urdf/velvet_fingers.transmission.xacro" />
  <!-- Include Utilities -->
  <xacro:include filename="$(find velvet_fingers_description)/urdf/utilities.xacro" />

  <!-- some constants -->
 <!-- <xacro:property name="safety_controller_k_pos" value="100" />
  <xacro:property name="safety_controller_k_vel" value="2" /> -->
  <xacro:property name="joint_damping" value="0.5" />
  <xacro:property name="max_effort" value="100"/>
  <xacro:property name="max_velocity" value="10"/>

  <xacro:macro name="velvet_fingers" params="parent name hardware_interface *origin">

    <!--joint between {parent} and palm -->
    <joint name="${parent}_joint" type="fixed">
      <insert_block name="origin"/>
      <parent link="${parent}"/>
      <child link="${name}_palm"/>
    </joint>

    <link name="${name}_palm">
      <inertial>
        <origin xyz="0.04 0.0 -0.01" rpy="0 0 0"/>
        <mass value="0.8"/>
        <inertia ixx="0.003"  ixy="0"  ixz="0" iyy="0.005" iyz="0" izz="0.004" />
      </inertial>

      <visual>
        <origin xyz="0 0 0" rpy="0 0 0"/>
        <geometry>
          <mesh filename="package://velvet_fingers_description/meshes/velvet_fingers_palm.stl"/>
        </geometry>
        <material name="Red"/>
      </visual>

      <collision>
        <origin xyz="0 0 0" rpy="0 0 0"/>
        <geometry>
          <mesh filename="package://velvet_fingers_description/meshes/velvet_fingers_palm.stl"/>
        </geometry>
        <material name="Red"/>
      </collision>
    </link>

    <!-- joint between palm and right finger -->
    <joint name="${name}_joint_1" type="revolute">
      <parent link="${name}_palm"/>
      <child link="${name}_right"/>
      <origin xyz="0.121 -0.016 0.0" rpy="0 0 ${-PI / 2}"/>
      <axis xyz="0 0 1"/>
      <limit lower="${0 * PI / 180}" upper="${90 * PI / 180}"
             effort="${max_effort}" velocity="${max_velocity}" />
      <!--   <safety_controller soft_lower_limit="${-168 * M_PI / 180}"
           soft_upper_limit="${168 * M_PI / 180}"
           k_position="${safety_controller_k_pos}"
           k_velocity="${safety_controller_k_vel}"/> -->
      <dynamics damping="${joint_damping}"/>
    </joint>

    <link name="${name}_right">
      <inertial>
        <origin xyz="0.01 0 0" rpy="0 0 0"/>
        <mass value="0.5"/>
        <inertia ixx="0.001"  ixy="0"  ixz="0" iyy="0.001" iyz="0" izz="0.001" />
      </inertial>

      <visual>
        <origin xyz="0 0 0" rpy="0 0 0"/>
        <geometry>
          <mesh filename="package://velvet_fingers_description/meshes/velvet_fingers_right.stl"/>
        </geometry>
        <material name="Orange"/>
      </visual>

      <collision>
        <origin xyz="0 0 0" rpy="0 0 0"/>
        <geometry>
          <mesh filename="package://velvet_fingers_description/meshes/velvet_fingers_right.stl"/>
        </geometry>
        <material name="Orange"/>
      </collision>
    </link>

    <!-- joint between palm and left finger -->
    <joint name="${name}_joint_2" type="revolute">
      <parent link="${name}_palm"/>
      <child link="${name}_left"/>
      <origin xyz="0.121 0.016 0.0" rpy="${PI} 0 ${PI / 2}"/>
      <axis xyz="0 0 1"/>
      <limit lower="${0 * PI / 180}" upper="${90 * PI / 180}"
             effort="${max_effort}" velocity="${max_velocity}" />
      <!--   <safety_controller soft_lower_limit="${-168 * M_PI / 180}"
           soft_upper_limit="${168 * M_PI / 180}"
           k_position="${safety_controller_k_pos}"
           k_velocity="${safety_controller_k_vel}"/> -->
      <dynamics damping="${joint_damping}"/>
      <mimic joint="${name}_joint_1"/>
    </joint>

    <link name="${name}_left">
      <inertial>
        <origin xyz="0.01 0 0" rpy="0 0 0"/>
        <mass value="0.5"/>
        <inertia ixx="0.001"  ixy="0"  ixz="0" iyy="0.001" iyz="0" izz="0.001" />
      </inertial>

      <visual>
        <origin xyz="0 0 0" rpy="0 0 0"/>
        <geometry>
          <mesh filename="package://velvet_fingers_description/meshes/velvet_fingers_left.stl"/> 
        </geometry>
        <material name="Orange"/>
      </visual>

      <collision>
        <origin xyz="0 0 0" rpy="0 0 0"/>
        <geometry>
          <mesh filename="package://velvet_fingers_description/meshes/velvet_fingers_left.stl"/>
        </geometry>
        <material name="Orange"/>
      </collision>
    </link>

    <!--Extensions -->
    <xacro:velvet_fingers_gazebo name="${name}" />
    <xacro:velvet_fingers_transmission name="${name}" hardware_interface="${hardware_interface}"/>

  </xacro:macro>

</robot>
